<?xml version="1.0" ?>
<!-- =================================================================================== -->
<!-- |    This document was autogenerated by xacro from src/vision_bot/description/robot.urdf.xacro | -->
<!-- |    EDITING THIS FILE BY HAND IS NOT RECOMMENDED                                 | -->
<!-- =================================================================================== -->
<robot name="robot">
  <!-- COLORS -->
  <material name="white">
    <color rgba="1 1 1 1"/>
  </material>
  <material name="orange">
    <color rgba="1 0.3 0.1 1"/>
  </material>
  <material name="blue">
    <color rgba="0 0.2588 0.51 1"/>
  </material>
  <material name="black">
    <color rgba="0 0 0 1"/>
  </material>
  <!-- BASE LINK -->
  <link name="base_link">

    </link>
  <!-- COMPONENTS -->
  <!-- Specify some standard inertial calculations https://en.wikipedia.org/wiki/List_of_moments_of_inertia -->
  <!-- These make use of xacro's mathematical functionality -->
  <!-- CHASSIS LINK -->
  <joint name="chassis_joint" type="fixed">
    <parent link="base_link"/>
    <child link="chassis"/>
    <origin xyz="0 0 0.018"/>
  </joint>
  <link name="chassis">
    <visual>
      <origin xyz="0.1 0 0.025"/>
      <geometry>
        <box size="0.2 0.135 0.05"/>
      </geometry>
      <material name="black"/>
    </visual>
    <collision>
      <origin xyz="0.1 0 0.025"/>
      <geometry>
        <box size="0.2 0.135 0.05"/>
      </geometry>
      <material name="black"/>
    </collision>
    <inertial>
      <origin rpy="0 0 0" xyz="0.1 0 0.025"/>
      <mass value="1.5"/>
      <inertia ixx="0.002590625" ixy="0.0" ixz="0.0" iyy="0.005312500000000001" iyz="0.0" izz="0.007278125000000002"/>
    </inertial>
  </link>
  <joint name="cpu_joint" type="fixed">
    <parent link="chassis"/>
    <child link="cpu_link"/>
    <origin rpy="0 0 0" xyz="0.1 0 0.05075"/>
  </joint>
  <link name="cpu_link">
    <visual>
      <geometry>
        <box size="0.085 0.056 0.0015"/>
      </geometry>
      <material name="orange"/>
    </visual>
    <collision>
      <geometry>
        <box size="0.085 0.056 0.0015"/>
      </geometry>
      <material name="orange"/>
    </collision>
    <inertial>
      <origin rpy="0 0 0" xyz="0 0 0.0"/>
      <mass value="0.1"/>
      <inertia ixx="2.6152083333333337e-05" ixy="0.0" ixz="0.0" iyy="6.022708333333334e-05" iyz="0.0" izz="8.634166666666669e-05"/>
    </inertial>
  </link>
  <!-- Specify some standard inertial calculations https://en.wikipedia.org/wiki/List_of_moments_of_inertia -->
  <!-- These make use of xacro's mathematical functionality -->
  <!-- LEFT REAR WHEEL LINK -->
  <joint name="rear_left_wheel_joint" type="continuous">
    <parent link="chassis"/>
    <child link="rear_left_wheel"/>
    <origin rpy="-1.5707963267948966 0 0" xyz="0.034 0.0775 0.016000000000000004"/>
    <axis xyz="0 0 1"/>
  </joint>
  <link name="rear_left_wheel">
    <visual>
      <geometry>
        <cylinder length="0.02" radius="0.034"/>
      </geometry>
      <material name="orange"/>
    </visual>
    <collision>
      <geometry>
        <cylinder length="0.02" radius="0.034"/>
      </geometry>
      <material name="orange"/>
    </collision>
    <inertial>
      <origin rpy="0 0 0" xyz="0 0 0"/>
      <mass value="0.1"/>
      <inertia ixx="3.223333333333334e-05" ixy="0.0" ixz="0.0" iyy="3.223333333333334e-05" iyz="0.0" izz="5.780000000000001e-05"/>
    </inertial>
  </link>
  <!-- RIGHT REAR WHEEL LINK -->
  <joint name="rear_right_wheel_joint" type="continuous">
    <parent link="chassis"/>
    <child link="rear_right_wheel"/>
    <origin rpy="1.5707963267948966 0 0" xyz="0.034 -0.0775 0.016000000000000004"/>
    <axis xyz="0 0 -1"/>
  </joint>
  <link name="rear_right_wheel">
    <visual>
      <geometry>
        <cylinder length="0.02" radius="0.034"/>
      </geometry>
      <material name="orange"/>
    </visual>
    <collision>
      <geometry>
        <cylinder length="0.02" radius="0.034"/>
      </geometry>
      <material name="orange"/>
    </collision>
    <inertial>
      <origin rpy="0 0 0" xyz="0 0 0"/>
      <mass value="0.1"/>
      <inertia ixx="3.223333333333334e-05" ixy="0.0" ixz="0.0" iyy="3.223333333333334e-05" iyz="0.0" izz="5.780000000000001e-05"/>
    </inertial>
  </link>
  <!-- LEFT FRONT WHEEL LINK -->
  <joint name="front_left_wheel_joint" type="continuous">
    <parent link="chassis"/>
    <child link="front_left_wheel"/>
    <origin rpy="-1.5707963267948966 0 0" xyz="0.166 0.0775 0.016000000000000004"/>
    <axis xyz="0 0 1"/>
  </joint>
  <link name="front_left_wheel">
    <visual>
      <geometry>
        <cylinder length="0.02" radius="0.034"/>
      </geometry>
      <material name="orange"/>
    </visual>
    <collision>
      <geometry>
        <cylinder length="0.02" radius="0.034"/>
      </geometry>
      <material name="orange"/>
    </collision>
    <inertial>
      <origin rpy="0 0 0" xyz="0 0 0"/>
      <mass value="0.1"/>
      <inertia ixx="3.223333333333334e-05" ixy="0.0" ixz="0.0" iyy="3.223333333333334e-05" iyz="0.0" izz="5.780000000000001e-05"/>
    </inertial>
  </link>
  <!-- RIGHT FRONT WHEEL LINK -->
  <joint name="front_right_wheel_joint" type="continuous">
    <parent link="chassis"/>
    <child link="front_right_wheel"/>
    <origin rpy="1.5707963267948966 0 0" xyz="0.166 -0.0775 0.016000000000000004"/>
    <axis xyz="0 0 -1"/>
  </joint>
  <link name="front_right_wheel">
    <visual>
      <geometry>
        <cylinder length="0.02" radius="0.034"/>
      </geometry>
      <material name="orange"/>
    </visual>
    <collision>
      <geometry>
        <cylinder length="0.02" radius="0.034"/>
      </geometry>
      <material name="orange"/>
    </collision>
    <inertial>
      <origin rpy="0 0 0" xyz="0 0 0"/>
      <mass value="0.1"/>
      <inertia ixx="3.223333333333334e-05" ixy="0.0" ixz="0.0" iyy="3.223333333333334e-05" iyz="0.0" izz="5.780000000000001e-05"/>
    </inertial>
  </link>
  <!-- Specify some standard inertial calculations https://en.wikipedia.org/wiki/List_of_moments_of_inertia -->
  <!-- These make use of xacro's mathematical functionality -->
  <joint name="camera_neck_joint" type="fixed">
    <parent link="chassis"/>
    <child link="camera_neck_link"/>
    <origin rpy="0 0 0" xyz="0.17 0 0.0575"/>
  </joint>
  <link name="camera_neck_link">
    <visual>
      <geometry>
        <box size="0.01 0.01 0.015"/>
      </geometry>
      <material name="orange"/>
    </visual>
  </link>
  <joint name="camera_joint" type="fixed">
    <parent link="camera_neck_link"/>
    <child link="camera_link"/>
    <origin rpy="0 0 0" xyz="0 0 0.0125"/>
  </joint>
  <link name="camera_link">
    <visual>
      <geometry>
        <box size="0.01 0.015 0.01"/>
      </geometry>
      <material name="white"/>
    </visual>
  </link>
  <joint name="camera_optical_joint" type="fixed">
    <parent link="camera_link"/>
    <child link="camera_link_optical"/>
    <origin rpy="-1.5707963267948966 0 -1.5707963267948966" xyz="0 0 0"/>
  </joint>
  <link name="camera_link_optical"/>
  <gazebo reference="camera_link">
    <sensor name="camera" type="camera">
      <update_rate>30</update_rate>
      <topic>camera/image_raw</topic>
      <camera>
        <camera_info_topic>camera/camera_info</camera_info_topic>
        <horizontal_fov>1.089</horizontal_fov>
        <image>
          <format>R8G8B8</format>
          <width>640</width>
          <height>480</height>
        </image>
        <clip>
          <near>0.05</near>
          <far>8.0</far>
        </clip>
      </camera>
      <always_on>true</always_on>
      <visualize>true</visualize>
    </sensor>
  </gazebo>
  <joint name="front_uss_joint" type="fixed">
    <parent link="chassis"/>
    <child link="front_uss_link"/>
    <origin rpy="0 0 0" xyz="0.20750000000000002 0 0.018"/>
  </joint>
  <link name="front_uss_link">
    <visual>
      <geometry>
        <box size="0.02 0.04 0.015"/>
      </geometry>
      <material name="blue"/>
    </visual>
  </link>
  <gazebo reference="front_uss_link">
    <sensor name="sonar_front" type="gpu_lidar">
      <topic>robot/sonar_front</topic>
      <pose> 0 0 0 0 0 0 </pose>
      <visualize>false</visualize>
      <update_rate>10</update_rate>
      <lidar>
        <scan>
          <horizontal>
            <samples>10</samples>
            <min_angle>-0.01</min_angle>
            <max_angle>0.01</max_angle>
          </horizontal>
        </scan>
        <range>
          <min>0.3</min>
          <max>12</max>
        </range>
      </lidar>
      <always_on>1</always_on>
      <visualize>true</visualize>
      <gz_frame_id>laser_frame</gz_frame_id>
    </sensor>
  </gazebo>
  <ros2_control name="vision_bot_hw" type="system">
    <hardware>
      <plugin>gz_ros2_control/GazeboSimSystem</plugin>
    </hardware>
    <joint name="rear_left_wheel_joint">
      <command_interface name="velocity"/>
      <state_interface name="position"/>
      <state_interface name="velocity"/>
    </joint>
    <joint name="rear_right_wheel_joint">
      <command_interface name="velocity"/>
      <state_interface name="position"/>
      <state_interface name="velocity"/>
    </joint>
    <joint name="front_left_wheel_joint">
      <command_interface name="velocity"/>
      <state_interface name="position"/>
      <state_interface name="velocity"/>
    </joint>
    <joint name="front_right_wheel_joint">
      <command_interface name="velocity"/>
      <state_interface name="position"/>
      <state_interface name="velocity"/>
    </joint>
  </ros2_control>
  <gazebo>
    <plugin filename="libgz_ros2_control-system.so" name="gz_ros2_control::GazeboSimROS2ControlPlugin">
      <parameters>/home/gasa14/Workspaces/dev_ws/install/vision_bot/share/vision_bot/config/controllers.yaml</parameters>
    </plugin>
    <plugin filename="gz-sim-sensors-system" name="gz::sim::systems::Sensors">
        </plugin>
  </gazebo>
</robot>
