<?xml version="1.0"?>
<!-- =================================================================================== -->
<!-- |    This document was autogenerated by xacro from robot.urdf.xacro               | -->
<!-- |    EDITING THIS FILE BY HAND IS NOT RECOMMENDED                                 | -->
<!-- =================================================================================== -->
<robot name="robot">
  <!-- COLORS -->
  <material name="white">
    <color rgba="0.8 0.8 0.8 1" />
  </material>
  <material name="orange">
    <color rgba="1 0.3 0.1 1" />
  </material>
  <material name="black">
    <color rgba="0.1 0.1 0.1 1" />
  </material>
  <material name="green">
    <color rgba="0.32 0.545 0.298 1" />
  </material>
  <!-- BASE LINK -->
  <link name="base_link" />
  <!-- COMPONENTS -->
  <!-- CHASSIS LINK -->
  <joint name="chassis_joint" type="fixed">
    <parent link="base_link" />
    <child link="chassis" />
    <origin xyz="0 0 0.037" />
  </joint>
  <link name="chassis">
    <visual>
      <origin xyz="0 0 0" />
      <geometry>
        <mesh
          filename="/home/gasa14/Workspaces/dev_ws/src/visionbot_description/description/meshes/robot_base_link.stl" />
      </geometry>
      <material name="black" />
    </visual>
    <collision>
      <origin xyz="0 0 0" />
      <geometry>
        <box size="0.17 0.1 0.035" />
      </geometry>
      <material name="black" />
    </collision>
    <inertial>
      <origin rpy="0 0 0" xyz="0 0 0" />
      <mass value="1.5" />
      <inertia ixx="0.0014031250000000003" ixy="0.0" ixz="0.0" iyy="0.0037656250000000007" iyz="0.0"
        izz="0.0048625000000000005" />
    </inertial>
  </link>
  <!-- CPU LINK -->
  <joint name="cpu_joint" type="fixed">
    <parent link="chassis" />
    <child link="cpu_link" />
    <origin rpy="1.5707963267948966 0 0" xyz="0 0 0.005" />
  </joint>
  <link name="cpu_link">
    <visual>
      <origin xyz="0 0 0" />
      <geometry>
        <mesh
          filename="/home/gasa14/Workspaces/dev_ws/src/visionbot_description/description/meshes/rpi5_link.stl" />
      </geometry>
      <material name="green" />
    </visual>
    <collision>
      <geometry>
        <box size="0.085 0.003 0.02" />
      </geometry>
      <material name="green" />
    </collision>
    <inertial>
      <origin rpy="0 0 0" xyz="0 0 0.0" />
      <mass value="0.1" />
      <inertia ixx="3.4083333333333335e-06" ixy="0.0" ixz="0.0" iyy="6.354166666666668e-05"
        iyz="0.0" izz="6.0283333333333346e-05" />
    </inertial>
  </link>
  <!-- LEFT REAR WHEEL LINK -->
  <joint name="rear_left_wheel_joint" type="continuous">
    <parent link="chassis" />
    <child link="rear_left_wheel" />
    <origin rpy="-1.5707963267948966 0 0" xyz="-0.066 0.076 -0.003999999999999997" />
    <axis xyz="0 0 1" />
  </joint>
  <link name="rear_left_wheel">
    <collision>
      <geometry>
        <cylinder length="0.022" radius="0.033" />
      </geometry>
      <material name="orange" />
    </collision>
    <inertial>
      <origin rpy="0 0 0" xyz="0 0 0" />
      <mass value="0.1" />
      <inertia ixx="3.125833333333334e-05" ixy="0.0" ixz="0.0" iyy="3.125833333333334e-05" iyz="0.0"
        izz="5.445000000000001e-05" />
    </inertial>
  </link>
  <!-- RIGHT REAR WHEEL LINK -->
  <joint name="rear_right_wheel_joint" type="continuous">
    <parent link="chassis" />
    <child link="rear_right_wheel" />
    <origin rpy="1.5707963267948966 0 0" xyz="-0.066 -0.076 -0.003999999999999997" />
    <axis xyz="0 0 -1" />
  </joint>
  <link name="rear_right_wheel">
    <collision>
      <geometry>
        <cylinder length="0.022" radius="0.033" />
      </geometry>
      <material name="orange" />
    </collision>
    <inertial>
      <origin rpy="0 0 0" xyz="0 0 0" />
      <mass value="0.1" />
      <inertia ixx="3.125833333333334e-05" ixy="0.0" ixz="0.0" iyy="3.125833333333334e-05" iyz="0.0"
        izz="5.445000000000001e-05" />
    </inertial>
  </link>
  <!-- LEFT FRONT WHEEL LINK -->
  <joint name="front_left_wheel_joint" type="continuous">
    <parent link="chassis" />
    <child link="front_left_wheel" />
    <origin rpy="-1.5707963267948966 0 0" xyz="0.066 0.076 -0.003999999999999997" />
    <axis xyz="0 0 1" />
  </joint>
  <link name="front_left_wheel">
    <collision>
      <geometry>
        <cylinder length="0.022" radius="0.033" />
      </geometry>
      <material name="orange" />
    </collision>
    <inertial>
      <origin rpy="0 0 0" xyz="0 0 0" />
      <mass value="0.1" />
      <inertia ixx="3.125833333333334e-05" ixy="0.0" ixz="0.0" iyy="3.125833333333334e-05" iyz="0.0"
        izz="5.445000000000001e-05" />
    </inertial>
  </link>
  <!-- RIGHT FRONT WHEEL LINK -->
  <joint name="front_right_wheel_joint" type="continuous">
    <parent link="chassis" />
    <child link="front_right_wheel" />
    <origin rpy="1.5707963267948966 0 0" xyz="0.066 -0.076 -0.003999999999999997" />
    <axis xyz="0 0 -1" />
  </joint>
  <link name="front_right_wheel">
    <collision>
      <geometry>
        <cylinder length="0.022" radius="0.033" />
      </geometry>
      <material name="orange" />
    </collision>
    <inertial>
      <origin rpy="0 0 0" xyz="0 0 0" />
      <mass value="0.1" />
      <inertia ixx="3.125833333333334e-05" ixy="0.0" ixz="0.0" iyy="3.125833333333334e-05" iyz="0.0"
        izz="5.445000000000001e-05" />
    </inertial>
  </link>
  <joint name="camera_neck_joint" type="fixed">
    <parent link="chassis" />
    <child link="camera_neck_link" />
    <origin rpy="0 0 0" xyz="0.06666666666666667 0 0.025" />
  </joint>
  <link name="camera_neck_link">
    <visual>
      <geometry>
        <box size="0.001 0.01 0.01" />
      </geometry>
      <material name="white" />
    </visual>
    <collision>
      <origin xyz="0 0 0" />
      <geometry>
        <box size="0.001 0.01 0.01" />
      </geometry>
      <material name="white" />
    </collision>
    <inertial>
      <origin rpy="0 0 0" xyz="0 0 0" />
      <mass value="0.1" />
      <inertia ixx="1.6666666666666667e-06" ixy="0.0" ixz="0.0" iyy="8.416666666666666e-07"
        iyz="0.0" izz="8.416666666666666e-07" />
    </inertial>
  </link>
  <joint name="camera_joint" type="fixed">
    <parent link="camera_neck_link" />
    <child link="camera_link" />
    <origin rpy="0 1.5707963267948966 0" xyz="0.0075 0 0.01" />
  </joint>
  <link name="camera_link">
    <visual>
      <origin xyz="0 0 0" />
      <geometry>
        <mesh
          filename="/home/gasa14/Workspaces/dev_ws/src/visionbot_description/description/meshes/rpi_camera_link.stl" />
      </geometry>
      <material name="green" />
    </visual>
  </link>
  <joint name="camera_optical_joint" type="fixed">
    <parent link="camera_link" />
    <child link="camera_link_optical" />
    <origin rpy="-1.5707963267948966 0 -1.5707963267948966" xyz="0 0 0" />
  </joint>
  <link name="camera_link_optical" />
  <gazebo reference="camera_link">
    <sensor name="camera" type="camera">
      <update_rate>30</update_rate>
      <topic>camera/image_raw</topic>
      <camera>
        <camera_info_topic>camera/camera_info</camera_info_topic>
        <horizontal_fov>2.09</horizontal_fov>
        <image>
          <format>R8G8B8</format>
          <width>1280</width>
          <height>720</height>
        </image>
        <clip>
          <near>0.05</near>
          <far>20.0</far>
        </clip>
      </camera>
      <always_on>true</always_on>
      <visualize>true</visualize>
    </sensor>
  </gazebo>
  <link name="lidar_link">
    <visual>
      <origin rpy="0 0 0" xyz="0 0 0" />
      <geometry>
        <mesh
          filename="/home/gasa14/Workspaces/dev_ws/src/visionbot_description/description/meshes/laser_link.stl" />
      </geometry>
      <material name="black" />
    </visual>
    <collision>
      <origin rpy="0 0 0" xyz="0 0 0" />
      <geometry>
        <mesh
          filename="/home/gasa14/Workspaces/dev_ws/src/visionbot_description/description/meshes/laser_link.stl" />
      </geometry>
    </collision>
    <inertial>
      <origin rpy="0 0 0" xyz="-0.011945780406062 -0.000381929217680526 -0.0170649378129477" />
      <mass value="0.073084435549317" />
      <inertia ixx="1.96074931730795E-05" ixy="-3.62091076640009E-07" ixz="4.28230084046735E-07"
        iyy="2.40983835136327E-05" iyz="1.50180909250652E-08" izz="4.14184164228595E-05" />
    </inertial>
  </link>
  <joint name="lidar_joint" type="fixed">
    <parent link="chassis" />
    <child link="lidar_link" />
    <origin rpy="0 0 3.141592653589793" xyz="0 0 0.060000000000000005" />
  </joint>
  <!-- <xacro:include filename="ros2_control.xacro" /> -->
  <ros2_control name="vision_bot" type="system">
    <hardware>
      <plugin>gz_ros2_control/GazeboSimSystem</plugin>
    </hardware>
    <joint name="rear_left_wheel_joint">
      <command_interface name="velocity">
        <param name="min">-1</param>
        <param name="max">1</param>
      </command_interface>
      <state_interface name="position" />
      <state_interface name="velocity" />
    </joint>
    <joint name="rear_right_wheel_joint">
      <command_interface name="velocity">
        <param name="min">-1</param>
        <param name="max">1</param>
      </command_interface>
      <state_interface name="position" />
      <state_interface name="velocity" />
    </joint>
    <joint name="front_left_wheel_joint">
      <command_interface name="velocity">
        <param name="min">-1</param>
        <param name="max">1</param>
      </command_interface>
      <state_interface name="position" />
      <state_interface name="velocity" />
    </joint>
    <joint name="front_right_wheel_joint">
      <command_interface name="velocity">
        <param name="min">-1</param>
        <param name="max">1</param>
      </command_interface>
      <state_interface name="position" />
      <state_interface name="velocity" />
    </joint>
  </ros2_control>
  <gazebo reference="rear_left_wheel">
    <mu1>100000000000000.0</mu1>
    <mu2>100000000000000.0</mu2>
    <kp>100000000000000.0</kp>
    <kd>10.0</kd>
    <minDepth>0.001</minDepth>
    <maxVel>0.1</maxVel>
    <fdir>1 0 0</fdir>
  </gazebo>
  <gazebo reference="rear_right_wheel">
    <mu1>100000000000000.0</mu1>
    <mu2>100000000000000.0</mu2>
    <kp>100000000000000.0</kp>
    <kd>10.0</kd>
    <minDepth>0.001</minDepth>
    <maxVel>0.1</maxVel>
    <fdir>1 0 0</fdir>
  </gazebo>
  <gazebo reference="front_left_wheel">
    <mu1>100000000000000.0</mu1>
    <mu2>100000000000000.0</mu2>
    <kp>100000000000000.0</kp>
    <kd>10.0</kd>
    <minDepth>0.001</minDepth>
    <maxVel>0.1</maxVel>
    <fdir>1 0 0</fdir>
  </gazebo>
  <gazebo reference="front_right_wheel">
    <mu1>100000000000000.0</mu1>
    <mu2>100000000000000.0</mu2>
    <kp>100000000000000.0</kp>
    <kd>10.0</kd>
    <minDepth>0.001</minDepth>
    <maxVel>0.1</maxVel>
    <fdir>1 0 0</fdir>
  </gazebo>
  <gazebo reference="lidar_link">
    <sensor name="lidar" type="gpu_lidar">
      <always_on>true</always_on>
      <visualize>true</visualize>
      <pose> 0 0 0 0 0 0 </pose>
      <topic>scan</topic>
      <update_rate>5</update_rate>
      <gz_frame_id>lidar_link</gz_frame_id>
      <ray>
        <scan>
          <horizontal>
            <samples>360</samples>
            <resolution>1.0</resolution>
            <min_angle>-3.14159</min_angle>
            <max_angle>3.14159</max_angle>
          </horizontal>
        </scan>
        <range>
          <min>0.12</min>
          <max>12.0</max>
          <resolution>0.02</resolution>
        </range>
        <noise>
          <type>gaussian</type>
          <mean>0.0</mean>
          <stddev>0.01</stddev>
        </noise>
      </ray>
    </sensor>
  </gazebo>
  <gazebo>
    <plugin filename="gz_ros2_control-system" name="gz_ros2_control::GazeboSimROS2ControlPlugin">
      <parameters>
        /home/gasa14/Workspaces/dev_ws/install/vision_bot/share/vision_bot/config/controllers.yaml</parameters>
    </plugin>
    <plugin filename="gz-sim-sensors-system" name="gz::sim::systems::Sensors">
      <render_engine>ogre2</render_engine>
    </plugin>
  </gazebo>
</robot>